#VRML_SIM R2021a utf8
WorldInfo {
  coordinateSystem "NUE"
}
Viewpoint {
  orientation -0.9999614052321173 -0.007224234164950953 -0.004999848691634757 1.2108364278178172
  position -0.06295929663688886 2.530301189909927 1.031619363067519
}
TexturedBackground {
}
TexturedBackgroundLight {
}
RectangleArena {
  floorSize 2.1445 1.4855
  floorTileSize 0.33 0.33
}
DEF MAZE Group {
  children [
    DEF cornerStone Solid {
      translation -0.7425 0.0325 -0.4125
      children [
        DEF cornerStone Shape {
          appearance PBRAppearance {
            baseColor 1 0 1
            roughness 0.5
          }
          geometry Box {
            size 0.015 0.065 0.015
          }
        }
      ]
      name "solid(4)"
      boundingObject USE cornerStone
      physics Physics {
        density 100
      }
    }
    DEF cornerStone Solid {
      translation 0.7425 0.0325 -0.4125
      children [
        DEF cornerStone Shape {
          appearance PBRAppearance {
            baseColor 1 0 1
            roughness 0.5
          }
          geometry Box {
            size 0.015 0.065 0.015
          }
        }
      ]
      name "solid(5)"
      boundingObject USE cornerStone
      physics Physics {
        density 100
      }
    }
    DEF cornerStone Solid {
      translation 0.7425 0.0325 0.4125
      children [
        DEF cornerStone Shape {
          appearance PBRAppearance {
            baseColor 1 0 1
            roughness 0.5
          }
          geometry Box {
            size 0.015 0.065 0.015
          }
        }
      ]
      name "solid(6)"
      boundingObject USE cornerStone
      physics Physics {
        density 100
      }
    }
    DEF cornerStone Solid {
      translation -0.7425 0.0325 0.4125
      children [
        DEF cornerStone Shape {
          appearance PBRAppearance {
            baseColor 1 0 1
            roughness 0.5
          }
          geometry Box {
            size 0.015 0.065 0.015
          }
        }
      ]
      name "solid(7)"
      boundingObject USE cornerStone
      physics Physics {
        density 100
      }
    }
    DEF hWall Solid {
      translation 0 0.0325 -0.4125
      children [
        DEF hWall Shape {
          appearance PBRAppearance {
            baseColor 1 0 0
            roughness 0.3
          }
          geometry Box {
            size 1.46 0.065 0.015
          }
        }
      ]
      name "solid(1)"
      boundingObject USE hWall
      physics Physics {
        density 100
      }
    }
    DEF hWall Solid {
      translation 0 0.0325 0.4125
      children [
        DEF hWall Shape {
          appearance PBRAppearance {
            baseColor 1 0 0
            roughness 0.3
          }
          geometry Box {
            size 1.46 0.065 0.015
          }
        }
      ]
      boundingObject USE hWall
      physics Physics {
        density 100
      }
    }
    DEF vWall Solid {
      translation -0.7425 0.0325 0
      children [
        DEF vWall Shape {
          appearance PBRAppearance {
            baseColor 0 0 1
            roughness 0.3
          }
          geometry Box {
            size 0.015 0.065 0.8
          }
        }
      ]
      name "solid(2)"
      boundingObject USE vWall
      physics Physics {
        density 100
      }
    }
    DEF vWall Solid {
      translation 0.7425 0.0325 0
      children [
        DEF vWall Shape {
          appearance PBRAppearance {
            baseColor 0 0 1
            roughness 0.3
          }
          geometry Box {
            size 0.015 0.065 0.8
          }
        }
      ]
      name "solid(3)"
      boundingObject USE vWall
      physics Physics {
        density 100
      }
    }
    DEF Pole MazeBlock {
      translation -0.905 0 -0.5775
      length 0.015
    }
    DEF Pole MazeBlock {
      translation -0.5775 0 -0.2475
      name "maze block(20)"
      length 0.015
    }
    DEF Pole MazeBlock {
      translation -0.4125 0 -0.2475
      name "maze block(21)"
      length 0.015
    }
    DEF Pole MazeBlock {
      translation -0.2475 0 -0.2475
      name "maze block(22)"
      length 0.015
    }
    DEF Pole MazeBlock {
      translation -0.0825 0 -0.2475
      name "maze block(23)"
      length 0.015
    }
    DEF Pole MazeBlock {
      translation 0.2475 0 -0.2475
      name "maze block(25)"
      length 0.015
    }
    DEF Pole MazeBlock {
      translation 0.4125 0 -0.2475
      name "maze block(26)"
      length 0.015
    }
    DEF Pole MazeBlock {
      translation -0.5775 0 -0.0825
      name "maze block(30)"
      length 0.015
    }
    DEF Pole MazeBlock {
      translation -0.4125 0 -0.0825
      name "maze block(31)"
      length 0.015
    }
    DEF Pole MazeBlock {
      translation -0.2475 0 -0.0825
      name "maze block(32)"
      length 0.015
    }
    DEF Pole MazeBlock {
      translation -0.0825 0 -0.0825
      name "maze block(33)"
      length 0.015
    }
    DEF Pole MazeBlock {
      translation 0.0825 0 -0.0825
      name "maze block(34)"
      length 0.015
    }
    DEF Pole MazeBlock {
      translation 0.2475 0 -0.0825
      name "maze block(35)"
      length 0.015
    }
    DEF Pole MazeBlock {
      translation 0.4125 0 -0.0825
      name "maze block(36)"
      length 0.015
    }
    DEF Pole MazeBlock {
      translation 0.5775 0 -0.0825
      name "maze block(37)"
      length 0.015
    }
    DEF Pole MazeBlock {
      translation -0.5775 0 0.0825
      name "maze block(40)"
      length 0.015
    }
    DEF Pole MazeBlock {
      translation -0.4125 0 0.0825
      name "maze block(41)"
      length 0.015
    }
    DEF Pole MazeBlock {
      translation -0.2475 0 0.0825
      name "maze block(42)"
      length 0.015
    }
    DEF Pole MazeBlock {
      translation -0.0825 0 0.0825
      name "maze block(43)"
      length 0.015
    }
    DEF Pole MazeBlock {
      translation 0.0825 0 0.0825
      name "maze block(44)"
      length 0.015
    }
    DEF Pole MazeBlock {
      translation 0.2475 0 0.0825
      name "maze block(45)"
      length 0.015
    }
    DEF Pole MazeBlock {
      translation 0.4125 0 0.0825
      name "maze block(46)"
      length 0.015
    }
    DEF Pole MazeBlock {
      translation -0.5775 0 0.2475
      name "maze block(50)"
      length 0.015
    }
    DEF Pole MazeBlock {
      translation -0.4125 0 0.2475
      name "maze block(51)"
      length 0.015
    }
    DEF Pole MazeBlock {
      translation -0.2475 0 0.2475
      name "maze block(52)"
      length 0.015
    }
    DEF Pole MazeBlock {
      translation -0.0825 0 0.2475
      name "maze block(53)"
      length 0.015
    }
    DEF Pole MazeBlock {
      translation 0.0825 0 0.2475
      name "maze block(54)"
      length 0.015
    }
    DEF Pole MazeBlock {
      translation 0.2475 0 0.2475
      name "maze block(55)"
      length 0.015
    }
    DEF Pole MazeBlock {
      translation 0.4125 0 0.2475
      name "maze block(56)"
      length 0.015
    }
    DEF Pole MazeBlock {
      translation 0.5775 0 0.2475
      name "maze block(57)"
      length 0.015
    }
    DEF hBlock MazeBlock {
      translation -0.66 0 -0.5775
      name "maze block(10)"
      length 0.14
    }
    DEF hBlock MazeBlock {
      translation 0.33 0 0.0825
      name "maze block(62)"
      length 0.14
    }
    DEF hBlock MazeBlock {
      translation 0.165 0 -0.0825
      name "maze block(61)"
      length 0.14
    }
    DEF hBlock MazeBlock {
      translation 0.165 0 0.0825
      name "maze block(60)"
      length 0.14
    }
    DEF hBlock MazeBlock {
      translation 0.33 0 -0.2475
      name "maze block(59)"
      length 0.14
    }
    DEF hBlock MazeBlock {
      translation 0.495 0 -0.0825
      name "maze block(58)"
      length 0.14
    }
    DEF hBlock MazeBlock {
      translation 0.495 0 0.2475
      name "maze block(39)"
      length 0.14
    }
    DEF hBlock MazeBlock {
      translation 0.165 0 0.2475
      name "maze block(29)"
      length 0.14
    }
    DEF vBlock MazeBlock {
      translation -0.905 0 -0.33
      rotation 0 1 0 1.5707996938995747
      name "maze block(78)"
      length 0.14
    }
    DEF vBlock MazeBlock {
      translation -0.4125 0 0
      rotation 0 1 0 1.5707996938995747
      name "maze block(65)"
      length 0.14
    }
    DEF vBlock MazeBlock {
      translation 0.2475 0 0.165
      rotation 0 1 0 1.5707996938995747
      name "maze block(64)"
      length 0.14
    }
    DEF vBlock MazeBlock {
      translation -0.2475 0 0
      rotation 0 1 0 1.5707996938995747
      name "maze block(63)"
      length 0.14
    }
    DEF vBlock MazeBlock {
      translation 0.2475 0 -0.165
      rotation 0 1 0 1.5707996938995747
      name "maze block(49)"
      length 0.14
    }
    DEF vBlock MazeBlock {
      translation 0.4125 0 -0.165
      rotation 0 1 0 1.5707996938995747
      name "maze block(11)"
      length 0.14
    }
    DEF vBlock MazeBlock {
      translation 0.4125 0 0.33
      rotation 0 1 0 1.5707996938995747
      name "maze block(48)"
      length 0.14
    }
    DEF hBlock MazeBlock {
      translation -0.495 0 -0.2475
      name "maze block(4)"
      length 0.14
    }
    DEF hBlock MazeBlock {
      translation -0.66 0 -0.0825
      name "maze block(6)"
      length 0.14
    }
    DEF hBlock MazeBlock {
      translation 0 0 -0.0825
      name "maze block(8)"
      length 0.14
    }
    DEF hBlock MazeBlock {
      translation 0 0 0.0825
      name "maze block(9)"
      length 0.14
    }
    DEF hBlock MazeBlock {
      translation -0.33 0 0.0825
      name "maze block(12)"
      length 0.14
    }
    DEF hBlock MazeBlock {
      translation -0.33 0 0.2475
      name "maze block(13)"
      length 0.14
    }
    DEF vBlock MazeBlock {
      translation -0.0825 0 0.33
      rotation 0 1 0 1.5707996938995747
      name "maze block(18)"
      length 0.14
    }
    DEF vBlock MazeBlock {
      translation -0.0825 0 -0.33
      rotation 0 1 0 1.5707996938995747
      name "maze block(2)"
      length 0.14
    }
    DEF vBlock MazeBlock {
      translation -0.0825 0 0
      rotation 0 1 0 1.5707996938995747
      name "maze block(17)"
      length 0.14
    }
    DEF vBlock MazeBlock {
      translation -0.2475 0 -0.165
      rotation 0 1 0 1.5707996938995747
      name "maze block(15)"
      length 0.14
    }
    DEF vBlock MazeBlock {
      translation -0.5775 0 0.33
      rotation 0 1 0 1.5707996938995747
      name "maze block(1)"
      length 0.14
    }
    DEF vBlock MazeBlock {
      translation -0.5775 0 0.165
      rotation 0 1 0 1.5707996938995747
      name "maze block(3)"
      length 0.14
    }
  ]
}
DEF z5205986 E-puck {
  translation -0.66 0 -0.33
  rotation 0 1 0 3.141592653589793
  controller "MTRN4110_PhaseD"
  camera_width 320
  camera_height 240
  turretSlot [
    DistanceSensor {
      rotation 0 1 0 -1.570845307179586
      name "dss"
    }
    DistanceSensor {
      rotation 0 1 0 2.3562
      name "dsnw"
    }
    DistanceSensor {
      rotation 0 1 0 0.7854
      name "dsne"
    }
    DistanceSensor {
      rotation 0 1 0 3.14159
      name "dsl"
    }
    DistanceSensor {
      name "dsr"
    }
    DistanceSensor {
      rotation 0 1 0 1.5708
      name "dsf"
    }
  ]
}
DEF OMNI_WHEELS Robot {
  translation 0 0.06 0
  scale 0.35 0.35 0.35
  children [
    DEF SOLID1 Solid {
      children [
        DEF WHEEL1 HingeJoint {
          jointParameters HingeJointParameters {
            axis 0 0 1
            anchor 0 0 0.1
          }
          device [
            RotationalMotor {
              name "wheel1"
            }
          ]
          endPoint Solid {
            translation 0 0 0.1
            rotation 0 0 1 0
            children [
              DEF sr1 HingeJoint {
                jointParameters HingeJointParameters {
                  anchor 0 0.05 0.02
                }
                endPoint Solid {
                  translation 0 0.05 0.02
                  rotation 1 0 0 0
                  children [
                    DEF r1 Transform {
                      rotation 0 0 1 1.5708
                      children [
                        DEF SMALL_WHEEL_SHAPE Shape {
                          appearance PBRAppearance {
                            baseColor 1 0.752941 0.796078
                            roughness 1
                            metalness 0
                          }
                          geometry Cylinder {
                            height 0.02
                            radius 0.01
                          }
                        }
                      ]
                    }
                  ]
                  name "sr1"
                  boundingObject USE r1
                  physics Physics {
                    density -1
                    mass 0.1
                  }
                }
              }
              DEF sr2 HingeJoint {
                jointParameters HingeJointParameters {
                  axis 0.707107 0.707107 0
                  anchor -0.03535 0.03535 0.02
                }
                endPoint Solid {
                  translation -0.03535 0.03535 0.02
                  rotation 0.7071067811865476 0.7071067811865476 0 0
                  children [
                    DEF r2 Transform {
                      rotation 0 0 1 2.27
                      children [
                        USE SMALL_WHEEL_SHAPE
                      ]
                    }
                  ]
                  name "sr2"
                  boundingObject USE r2
                  physics Physics {
                    density -1
                    mass 0.1
                  }
                }
              }
              DEF sr3 HingeJoint {
                jointParameters HingeJointParameters {
                  anchor 0 -0.05 0.02
                }
                endPoint Solid {
                  translation 0 -0.05 0.02
                  rotation 1 0 0 0
                  children [
                    DEF r3 Transform {
                      rotation 0 0 1 1.5708
                      children [
                        USE SMALL_WHEEL_SHAPE
                      ]
                    }
                  ]
                  name "sr3"
                  boundingObject USE r3
                  physics Physics {
                    density -1
                    mass 0.1
                  }
                }
              }
              DEF sr4 HingeJoint {
                jointParameters HingeJointParameters {
                  axis 0.707107 0.707107 0
                  anchor 0.03535 -0.03535 0.02
                }
                endPoint Solid {
                  translation 0.03535 -0.03535 0.02
                  rotation 0.7071067811865476 0.7071067811865476 0 0
                  children [
                    DEF r4 Transform {
                      rotation 0 0 1 2.27
                      children [
                        USE SMALL_WHEEL_SHAPE
                      ]
                    }
                  ]
                  name "sr4"
                  boundingObject USE r4
                  physics Physics {
                    density -1
                    mass 0.1
                  }
                }
              }
              DEF sr5 HingeJoint {
                jointParameters HingeJointParameters {
                  axis 0 1 0
                  anchor -0.05 0 0.02
                }
                endPoint Solid {
                  translation -0.05 0 0.02
                  children [
                    DEF r5 Transform {
                      children [
                        USE SMALL_WHEEL_SHAPE
                      ]
                    }
                  ]
                  name "sr5"
                  boundingObject USE r5
                  physics Physics {
                    density -1
                    mass 0.1
                  }
                }
              }
              DEF sr6 HingeJoint {
                jointParameters HingeJointParameters {
                  axis 0 1 0
                  anchor 0.05 0 0.02
                }
                endPoint Solid {
                  translation 0.05 0 0.02
                  children [
                    DEF r6 Transform {
                      children [
                        USE SMALL_WHEEL_SHAPE
                      ]
                    }
                  ]
                  name "sr6"
                  boundingObject USE r6
                  physics Physics {
                    density -1
                    mass 0.1
                  }
                }
              }
              DEF sr7 HingeJoint {
                jointParameters HingeJointParameters {
                  axis -0.707107 0.707107 0
                  anchor -0.03535 -0.03535 0.02
                }
                endPoint Solid {
                  translation -0.03535 -0.03535 0.02
                  rotation -0.7071067811865476 0.7071067811865476 0 0
                  children [
                    DEF r7 Transform {
                      rotation 0 0 1 0.76
                      children [
                        USE SMALL_WHEEL_SHAPE
                      ]
                    }
                  ]
                  name "sr7"
                  boundingObject USE r7
                  physics Physics {
                    density -1
                    mass 0.1
                  }
                }
              }
              DEF sr8 HingeJoint {
                jointParameters HingeJointParameters {
                  axis -0.707107 0.707107 0
                  anchor 0.03535 0.03535 0.02
                }
                endPoint Solid {
                  translation 0.03535 0.03535 0.02
                  rotation -0.7071067811865476 0.7071067811865476 0 0
                  children [
                    DEF r8 Transform {
                      rotation 0 0 1 0.76
                      children [
                        USE SMALL_WHEEL_SHAPE
                      ]
                    }
                  ]
                  name "sr8"
                  boundingObject USE r8
                  physics Physics {
                    density -1
                    mass 0.1
                  }
                }
              }
              DEF WHEEL_TRANS Transform {
                translation 0 0 0.02
                rotation 1 0 0 1.5708
                children [
                  DEF WHEEL_SHAPE Shape {
                    appearance PBRAppearance {
                      baseColor 0.678431 0.847059 0.901961
                      roughness 1
                      metalness 0
                    }
                    geometry Cylinder {
                      height 0.02
                      radius 0.05
                      subdivision 20
                    }
                  }
                ]
              }
            ]
            boundingObject Transform {
              translation 0 0 0.02
              rotation 1 0 0 1.5708
              children [
                DEF wheel1 Shape {
                  appearance PBRAppearance {
                    baseColor 0.8 0.8 0.8
                    transparency 0.12999999523162842
                    roughness 1
                    metalness 0
                    emissiveColor 0 1 0
                  }
                  geometry Cylinder {
                    height 0.02
                    radius 0.05
                  }
                }
              ]
            }
            physics Physics {
            }
          }
        }
      ]
      name "wheel1"
      boundingObject DEF DUMMY Sphere {
        radius 0.01
      }
      physics Physics {
      }
    }
    DEF SOLID2 Solid {
      rotation 0 1 0 2.09
      children [
        DEF WHEEL2 HingeJoint {
          jointParameters HingeJointParameters {
            axis 0 0 1
            anchor 0 0 0.1
          }
          device [
            RotationalMotor {
              name "wheel2"
            }
          ]
          endPoint Solid {
            translation 0 0 0.1
            rotation 0 0 1 0.00240580999995935
            children [
              DEF sr1 HingeJoint {
                jointParameters HingeJointParameters {
                  anchor 0 0.05 0.02
                }
                endPoint Solid {
                  translation 0 0.05 0.02
                  rotation 1 0 0 0
                  children [
                    USE r1
                  ]
                  name "sr1"
                  boundingObject USE r1
                  physics Physics {
                    density -1
                    mass 0.1
                  }
                }
              }
              DEF sr2 HingeJoint {
                jointParameters HingeJointParameters {
                  axis 0.707107 0.707107 0
                  anchor -0.03535 0.03535 0.02
                }
                endPoint Solid {
                  translation -0.03535 0.03535 0.02
                  rotation 0.7071067811865476 0.7071067811865476 0 0
                  children [
                    USE r2
                  ]
                  name "sr2"
                  boundingObject USE r2
                  physics Physics {
                    density -1
                    mass 0.1
                  }
                }
              }
              DEF sr3 HingeJoint {
                jointParameters HingeJointParameters {
                  anchor 0 -0.05 0.02
                }
                endPoint Solid {
                  translation 0 -0.05 0.02
                  rotation 1 0 0 0
                  children [
                    USE r3
                  ]
                  name "sr3"
                  boundingObject USE r3
                  physics Physics {
                    density -1
                    mass 0.1
                  }
                }
              }
              DEF sr4 HingeJoint {
                jointParameters HingeJointParameters {
                  axis 0.707107 0.707107 0
                  anchor 0.03535 -0.03535 0.02
                }
                endPoint Solid {
                  translation 0.03535 -0.03535 0.02
                  rotation 0.7071067811865476 0.7071067811865476 0 0
                  children [
                    USE r4
                  ]
                  name "sr4"
                  boundingObject USE r4
                  physics Physics {
                    density -1
                    mass 0.1
                  }
                }
              }
              DEF sr5 HingeJoint {
                jointParameters HingeJointParameters {
                  axis 0 1 0
                  anchor -0.05 0 0.02
                }
                endPoint Solid {
                  translation -0.05 0 0.02
                  children [
                    USE r5
                  ]
                  name "sr5"
                  boundingObject USE r5
                  physics Physics {
                    density -1
                    mass 0.1
                  }
                }
              }
              DEF sr6 HingeJoint {
                jointParameters HingeJointParameters {
                  axis 0 1 0
                  anchor 0.05 0 0.02
                }
                endPoint Solid {
                  translation 0.05 0 0.02
                  children [
                    USE r6
                  ]
                  name "sr6"
                  boundingObject USE r6
                  physics Physics {
                    density -1
                    mass 0.1
                  }
                }
              }
              DEF sr7 HingeJoint {
                jointParameters HingeJointParameters {
                  axis -0.707107 0.707107 0
                  anchor -0.03535 -0.03535 0.02
                }
                endPoint Solid {
                  translation -0.03535 -0.03535 0.02
                  rotation -0.7071067811865476 0.7071067811865476 0 0
                  children [
                    USE r7
                  ]
                  name "sr7"
                  boundingObject USE r7
                  physics Physics {
                    density -1
                    mass 0.1
                  }
                }
              }
              DEF sr8 HingeJoint {
                jointParameters HingeJointParameters {
                  axis -0.707107 0.707107 0
                  anchor 0.03535 0.03535 0.02
                }
                endPoint Solid {
                  translation 0.03535 0.03535 0.02
                  rotation -0.7071067811865476 0.7071067811865476 0 0
                  children [
                    USE r8
                  ]
                  name "sr8"
                  boundingObject USE r8
                  physics Physics {
                    density -1
                    mass 0.1
                  }
                }
              }
              USE WHEEL_TRANS
            ]
            boundingObject Transform {
              translation 0 0 0.02
              rotation 1 0 0 1.5708
              children [
                DEF wheel1 Shape {
                  appearance PBRAppearance {
                    baseColor 0.8 0.8 0.8
                    transparency 0.12999999523162842
                    roughness 1
                    metalness 0
                    emissiveColor 0 1 0
                  }
                  geometry Cylinder {
                    height 0.02
                    radius 0.05
                  }
                }
              ]
            }
            physics Physics {
            }
          }
        }
      ]
      name "wheel2"
      boundingObject USE DUMMY
      physics Physics {
      }
    }
    DEF SOLID3 Solid {
      rotation 0 1 0 4.18
      children [
        DEF WHEEL3 HingeJoint {
          jointParameters HingeJointParameters {
            axis 0 0 1
            anchor 0 0 0.1
          }
          device [
            RotationalMotor {
              name "wheel3"
            }
          ]
          endPoint Solid {
            translation 0 0 0.1
            rotation 0 0 1 0.0039094400000208316
            children [
              DEF sr1 HingeJoint {
                jointParameters HingeJointParameters {
                  anchor 0 0.05 0.02
                }
                endPoint Solid {
                  translation 0 0.05 0.02
                  rotation 1 0 0 0
                  children [
                    USE r1
                  ]
                  name "sr1"
                  boundingObject USE r1
                  physics Physics {
                    density -1
                    mass 0.1
                  }
                }
              }
              DEF sr2 HingeJoint {
                jointParameters HingeJointParameters {
                  axis 0.707107 0.707107 0
                  anchor -0.03535 0.03535 0.02
                }
                endPoint Solid {
                  translation -0.03535 0.03535 0.02
                  rotation 0.7071067811865476 0.7071067811865476 0 0
                  children [
                    USE r2
                  ]
                  name "sr2"
                  boundingObject USE r2
                  physics Physics {
                    density -1
                    mass 0.1
                  }
                }
              }
              DEF sr3 HingeJoint {
                jointParameters HingeJointParameters {
                  anchor 0 -0.05 0.02
                }
                endPoint Solid {
                  translation 0 -0.05 0.02
                  rotation 1 0 0 0
                  children [
                    USE r3
                  ]
                  name "sr3"
                  boundingObject USE r3
                  physics Physics {
                    density -1
                    mass 0.1
                  }
                }
              }
              DEF sr4 HingeJoint {
                jointParameters HingeJointParameters {
                  axis 0.707107 0.707107 0
                  anchor 0.03535 -0.03535 0.02
                }
                endPoint Solid {
                  translation 0.03535 -0.03535 0.02
                  rotation 0.7071067811865476 0.7071067811865476 0 0
                  children [
                    USE r4
                  ]
                  name "sr4"
                  boundingObject USE r4
                  physics Physics {
                    density -1
                    mass 0.1
                  }
                }
              }
              DEF sr5 HingeJoint {
                jointParameters HingeJointParameters {
                  axis 0 1 0
                  anchor -0.05 0 0.02
                }
                endPoint Solid {
                  translation -0.05 0 0.02
                  children [
                    USE r5
                  ]
                  name "sr5"
                  boundingObject USE r5
                  physics Physics {
                    density -1
                    mass 0.1
                  }
                }
              }
              DEF sr6 HingeJoint {
                jointParameters HingeJointParameters {
                  axis 0 1 0
                  anchor 0.05 0 0.02
                }
                endPoint Solid {
                  translation 0.05 0 0.02
                  children [
                    USE r6
                  ]
                  name "sr6"
                  boundingObject USE r6
                  physics Physics {
                    density -1
                    mass 0.1
                  }
                }
              }
              DEF sr7 HingeJoint {
                jointParameters HingeJointParameters {
                  axis -0.707107 0.707107 0
                  anchor -0.03535 -0.03535 0.02
                }
                endPoint Solid {
                  translation -0.03535 -0.03535 0.02
                  rotation -0.7071067811865476 0.7071067811865476 0 0
                  children [
                    USE r7
                  ]
                  name "sr7"
                  boundingObject USE r7
                  physics Physics {
                    density -1
                    mass 0.1
                  }
                }
              }
              DEF sr8 HingeJoint {
                jointParameters HingeJointParameters {
                  axis -0.707107 0.707107 0
                  anchor 0.03535 0.03535 0.02
                }
                endPoint Solid {
                  translation 0.03535 0.03535 0.02
                  rotation -0.7071067811865476 0.7071067811865476 0 0
                  children [
                    USE r8
                  ]
                  name "sr8"
                  boundingObject USE r8
                  physics Physics {
                    density -1
                    mass 0.1
                  }
                }
              }
              USE WHEEL_TRANS
            ]
            boundingObject Transform {
              translation 0 0 0.02
              rotation 1 0 0 1.5708
              children [
                DEF wheel1 Shape {
                  appearance PBRAppearance {
                    baseColor 0.8 0.8 0.8
                    transparency 0.12999999523162842
                    roughness 1
                    metalness 0
                    emissiveColor 0 1 0
                  }
                  geometry Cylinder {
                    height 0.02
                    radius 0.05
                  }
                }
              ]
            }
            physics Physics {
            }
          }
        }
      ]
      name "wheel3"
      boundingObject USE DUMMY
      physics Physics {
      }
    }
    DEF BODY_TRANS Transform {
      translation 0 0.03 0
      children [
        Shape {
          appearance PBRAppearance {
            baseColor 0.564706 0.933333 0.564706
            roughness 1
            metalness 0
          }
          geometry Cylinder {
            height 0.15
            radius 0.1
            subdivision 18
          }
        }
      ]
    }
  ]
  name "omniWheeledRobot"
  boundingObject USE BODY_TRANS
  physics Physics {
  }
  controller "MTRN4110_PhaseD"
}
